Workbook

Sheet 📊 Dashboard
A1: Anubis v6.1 — Threat Intelligence Dashboard
A2: Generated: 2026-02-26 00:15 | By Ramiz Alsafi | J2: Risk Level | K2: Count
A3: Threat Type | B3: Total | C3: P1 (Urgent) | D3: P2 (High) | E3: KEV Active | F3: Critical | G3: High | J3: CRITICAL | K3: =COUNTIF('Threat Intelligence'!$H:$H,"CRITICAL")
A4: ABUSE_IP | B4: =COUNTIF('Threat Intelligence'!$A:$A,A4) | C4: =COUNTIFS('Threat Intelligence'!$A:$A,A4,'Threat Intelligence'!$Q:$Q,"P1") | D4: =COUNTIFS('Threat Intelligence'!$A:$A,A4,'Threat Intelligence'!$Q:$Q,"P2") | E4: =COUNTIFS('Threat Intelligence'!$A:$A,A4,'Threat Intelligence'!$J:$J,"YES") | F4: =COUNTIFS('Threat Intelligence'!$A:$A,A4,'Threat Intelligence'!$E:$E,"CRITICAL") | G4: =COUNTIFS('Threat Intelligence'!$A:$A,A4,'Threat Intelligence'!$E:$E,"HIGH") | J4: HIGH | K4: =COUNTIF('Threat Intelligence'!$H:$H,"HIGH")
A5: BLOCKLIST_DE | B5: =COUNTIF('Threat Intelligence'!$A:$A,A5) | C5: =COUNTIFS('Threat Intelligence'!$A:$A,A5,'Threat Intelligence'!$Q:$Q,"P1") | D5: =COUNTIFS('Threat Intelligence'!$A:$A,A5,'Threat Intelligence'!$Q:$Q,"P2") | E5: =COUNTIFS('Threat Intelligence'!$A:$A,A5,'Threat Intelligence'!$J:$J,"YES") | F5: =COUNTIFS('Threat Intelligence'!$A:$A,A5,'Threat Intelligence'!$E:$E,"CRITICAL") | G5: =COUNTIFS('Threat Intelligence'!$A:$A,A5,'Threat Intelligence'!$E:$E,"HIGH") | J5: MEDIUM | K5: =COUNTIF('Threat Intelligence'!$H:$H,"MEDIUM")
A6: CENSYS_EXPOSED | B6: =COUNTIF('Threat Intelligence'!$A:$A,A6) | C6: =COUNTIFS('Threat Intelligence'!$A:$A,A6,'Threat Intelligence'!$Q:$Q,"P1") | D6: =COUNTIFS('Threat Intelligence'!$A:$A,A6,'Threat Intelligence'!$Q:$Q,"P2") | E6: =COUNTIFS('Threat Intelligence'!$A:$A,A6,'Threat Intelligence'!$J:$J,"YES") | F6: =COUNTIFS('Threat Intelligence'!$A:$A,A6,'Threat Intelligence'!$E:$E,"CRITICAL") | G6: =COUNTIFS('Threat Intelligence'!$A:$A,A6,'Threat Intelligence'!$E:$E,"HIGH") | J6: LOW | K6: =COUNTIF('Threat Intelligence'!$H:$H,"LOW")
A7: CVE | B7: =COUNTIF('Threat Intelligence'!$A:$A,A7) | C7: =COUNTIFS('Threat Intelligence'!$A:$A,A7,'Threat Intelligence'!$Q:$Q,"P1") | D7: =COUNTIFS('Threat Intelligence'!$A:$A,A7,'Threat Intelligence'!$Q:$Q,"P2") | E7: =COUNTIFS('Threat Intelligence'!$A:$A,A7,'Threat Intelligence'!$J:$J,"YES") | F7: =COUNTIFS('Threat Intelligence'!$A:$A,A7,'Threat Intelligence'!$E:$E,"CRITICAL") | G7: =COUNTIFS('Threat Intelligence'!$A:$A,A7,'Threat Intelligence'!$E:$E,"HIGH") | J7: Priority | K7: Count
A8: EMERGING_THREAT_IP | B8: =COUNTIF('Threat Intelligence'!$A:$A,A8) | C8: =COUNTIFS('Threat Intelligence'!$A:$A,A8,'Threat Intelligence'!$Q:$Q,"P1") | D8: =COUNTIFS('Threat Intelligence'!$A:$A,A8,'Threat Intelligence'!$Q:$Q,"P2") | E8: =COUNTIFS('Threat Intelligence'!$A:$A,A8,'Threat Intelligence'!$J:$J,"YES") | F8: =COUNTIFS('Threat Intelligence'!$A:$A,A8,'Threat Intelligence'!$E:$E,"CRITICAL") | G8: =COUNTIFS('Threat Intelligence'!$A:$A,A8,'Threat Intelligence'!$E:$E,"HIGH") | J8: P1 | K8: =COUNTIF('Threat Intelligence'!$Q:$Q,"P1")
A9: EXPLOIT | B9: =COUNTIF('Threat Intelligence'!$A:$A,A9) | C9: =COUNTIFS('Threat Intelligence'!$A:$A,A9,'Threat Intelligence'!$Q:$Q,"P1") | D9: =COUNTIFS('Threat Intelligence'!$A:$A,A9,'Threat Intelligence'!$Q:$Q,"P2") | E9: =COUNTIFS('Threat Intelligence'!$A:$A,A9,'Threat Intelligence'!$J:$J,"YES") | F9: =COUNTIFS('Threat Intelligence'!$A:$A,A9,'Threat Intelligence'!$E:$E,"CRITICAL") | G9: =COUNTIFS('Threat Intelligence'!$A:$A,A9,'Threat Intelligence'!$E:$E,"HIGH") | J9: P2 | K9: =COUNTIF('Threat Intelligence'!$Q:$Q,"P2")
A10: FEODO_C2 | B10: =COUNTIF('Threat Intelligence'!$A:$A,A10) | C10: =COUNTIFS('Threat Intelligence'!$A:$A,A10,'Threat Intelligence'!$Q:$Q,"P1") | D10: =COUNTIFS('Threat Intelligence'!$A:$A,A10,'Threat Intelligence'!$Q:$Q,"P2") | E10: =COUNTIFS('Threat Intelligence'!$A:$A,A10,'Threat Intelligence'!$J:$J,"YES") | F10: =COUNTIFS('Threat Intelligence'!$A:$A,A10,'Threat Intelligence'!$E:$E,"CRITICAL") | G10: =COUNTIFS('Threat Intelligence'!$A:$A,A10,'Threat Intelligence'!$E:$E,"HIGH") | J10: P3 | K10: =COUNTIF('Threat Intelligence'!$Q:$Q,"P3")
A11: FIREHOL_THREAT | B11: =COUNTIF('Threat Intelligence'!$A:$A,A11) | C11: =COUNTIFS('Threat Intelligence'!$A:$A,A11,'Threat Intelligence'!$Q:$Q,"P1") | D11: =COUNTIFS('Threat Intelligence'!$A:$A,A11,'Threat Intelligence'!$Q:$Q,"P2") | E11: =COUNTIFS('Threat Intelligence'!$A:$A,A11,'Threat Intelligence'!$J:$J,"YES") | F11: =COUNTIFS('Threat Intelligence'!$A:$A,A11,'Threat Intelligence'!$E:$E,"CRITICAL") | G11: =COUNTIFS('Threat Intelligence'!$A:$A,A11,'Threat Intelligence'!$E:$E,"HIGH") | J11: P4 | K11: =COUNTIF('Threat Intelligence'!$Q:$Q,"P4")
A12: FIREWALL_ADVISORY | B12: =COUNTIF('Threat Intelligence'!$A:$A,A12) | C12: =COUNTIFS('Threat Intelligence'!$A:$A,A12,'Threat Intelligence'!$Q:$Q,"P1") | D12: =COUNTIFS('Threat Intelligence'!$A:$A,A12,'Threat Intelligence'!$Q:$Q,"P2") | E12: =COUNTIFS('Threat Intelligence'!$A:$A,A12,'Threat Intelligence'!$J:$J,"YES") | F12: =COUNTIFS('Threat Intelligence'!$A:$A,A12,'Threat Intelligence'!$E:$E,"CRITICAL") | G12: =COUNTIFS('Threat Intelligence'!$A:$A,A12,'Threat Intelligence'!$E:$E,"HIGH") | J12: Threat Type | K12: Count
A13: GH_ADVISORY | B13: =COUNTIF('Threat Intelligence'!$A:$A,A13) | C13: =COUNTIFS('Threat Intelligence'!$A:$A,A13,'Threat Intelligence'!$Q:$Q,"P1") | D13: =COUNTIFS('Threat Intelligence'!$A:$A,A13,'Threat Intelligence'!$Q:$Q,"P2") | E13: =COUNTIFS('Threat Intelligence'!$A:$A,A13,'Threat Intelligence'!$J:$J,"YES") | F13: =COUNTIFS('Threat Intelligence'!$A:$A,A13,'Threat Intelligence'!$E:$E,"CRITICAL") | G13: =COUNTIFS('Threat Intelligence'!$A:$A,A13,'Threat Intelligence'!$E:$E,"HIGH") | J13: =A4 | K13: =B4
A14: MAL_URL | B14: =COUNTIF('Threat Intelligence'!$A:$A,A14) | C14: =COUNTIFS('Threat Intelligence'!$A:$A,A14,'Threat Intelligence'!$Q:$Q,"P1") | D14: =COUNTIFS('Threat Intelligence'!$A:$A,A14,'Threat Intelligence'!$Q:$Q,"P2") | E14: =COUNTIFS('Threat Intelligence'!$A:$A,A14,'Threat Intelligence'!$J:$J,"YES") | F14: =COUNTIFS('Threat Intelligence'!$A:$A,A14,'Threat Intelligence'!$E:$E,"CRITICAL") | G14: =COUNTIFS('Threat Intelligence'!$A:$A,A14,'Threat Intelligence'!$E:$E,"HIGH") | J14: =A5 | K14: =B5
A15: MSF_MODULE | B15: =COUNTIF('Threat Intelligence'!$A:$A,A15) | C15: =COUNTIFS('Threat Intelligence'!$A:$A,A15,'Threat Intelligence'!$Q:$Q,"P1") | D15: =COUNTIFS('Threat Intelligence'!$A:$A,A15,'Threat Intelligence'!$Q:$Q,"P2") | E15: =COUNTIFS('Threat Intelligence'!$A:$A,A15,'Threat Intelligence'!$J:$J,"YES") | F15: =COUNTIFS('Threat Intelligence'!$A:$A,A15,'Threat Intelligence'!$E:$E,"CRITICAL") | G15: =COUNTIFS('Threat Intelligence'!$A:$A,A15,'Threat Intelligence'!$E:$E,"HIGH") | J15: =A6 | K15: =B6
A16: MSRC_UPDATE | B16: =COUNTIF('Threat Intelligence'!$A:$A,A16) | C16: =COUNTIFS('Threat Intelligence'!$A:$A,A16,'Threat Intelligence'!$Q:$Q,"P1") | D16: =COUNTIFS('Threat Intelligence'!$A:$A,A16,'Threat Intelligence'!$Q:$Q,"P2") | E16: =COUNTIFS('Threat Intelligence'!$A:$A,A16,'Threat Intelligence'!$J:$J,"YES") | F16: =COUNTIFS('Threat Intelligence'!$A:$A,A16,'Threat Intelligence'!$E:$E,"CRITICAL") | G16: =COUNTIFS('Threat Intelligence'!$A:$A,A16,'Threat Intelligence'!$E:$E,"HIGH") | J16: =A7 | K16: =B7
A17: NEWS_ALERT | B17: =COUNTIF('Threat Intelligence'!$A:$A,A17) | C17: =COUNTIFS('Threat Intelligence'!$A:$A,A17,'Threat Intelligence'!$Q:$Q,"P1") | D17: =COUNTIFS('Threat Intelligence'!$A:$A,A17,'Threat Intelligence'!$Q:$Q,"P2") | E17: =COUNTIFS('Threat Intelligence'!$A:$A,A17,'Threat Intelligence'!$J:$J,"YES") | F17: =COUNTIFS('Threat Intelligence'!$A:$A,A17,'Threat Intelligence'!$E:$E,"CRITICAL") | G17: =COUNTIFS('Threat Intelligence'!$A:$A,A17,'Threat Intelligence'!$E:$E,"HIGH") | J17: =A8 | K17: =B8
A18: OTX_PULSE | B18: =COUNTIF('Threat Intelligence'!$A:$A,A18) | C18: =COUNTIFS('Threat Intelligence'!$A:$A,A18,'Threat Intelligence'!$Q:$Q,"P1") | D18: =COUNTIFS('Threat Intelligence'!$A:$A,A18,'Threat Intelligence'!$Q:$Q,"P2") | E18: =COUNTIFS('Threat Intelligence'!$A:$A,A18,'Threat Intelligence'!$J:$J,"YES") | F18: =COUNTIFS('Threat Intelligence'!$A:$A,A18,'Threat Intelligence'!$E:$E,"CRITICAL") | G18: =COUNTIFS('Threat Intelligence'!$A:$A,A18,'Threat Intelligence'!$E:$E,"HIGH") | J18: =A9 | K18: =B9
A19: PATCH_TUESDAY | B19: =COUNTIF('Threat Intelligence'!$A:$A,A19) | C19: =COUNTIFS('Threat Intelligence'!$A:$A,A19,'Threat Intelligence'!$Q:$Q,"P1") | D19: =COUNTIFS('Threat Intelligence'!$A:$A,A19,'Threat Intelligence'!$Q:$Q,"P2") | E19: =COUNTIFS('Threat Intelligence'!$A:$A,A19,'Threat Intelligence'!$J:$J,"YES") | F19: =COUNTIFS('Threat Intelligence'!$A:$A,A19,'Threat Intelligence'!$E:$E,"CRITICAL") | G19: =COUNTIFS('Threat Intelligence'!$A:$A,A19,'Threat Intelligence'!$E:$E,"HIGH") | J19: =A10 | K19: =B10
A20: PHISH | B20: =COUNTIF('Threat Intelligence'!$A:$A,A20) | C20: =COUNTIFS('Threat Intelligence'!$A:$A,A20,'Threat Intelligence'!$Q:$Q,"P1") | D20: =COUNTIFS('Threat Intelligence'!$A:$A,A20,'Threat Intelligence'!$Q:$Q,"P2") | E20: =COUNTIFS('Threat Intelligence'!$A:$A,A20,'Threat Intelligence'!$J:$J,"YES") | F20: =COUNTIFS('Threat Intelligence'!$A:$A,A20,'Threat Intelligence'!$E:$E,"CRITICAL") | G20: =COUNTIFS('Threat Intelligence'!$A:$A,A20,'Threat Intelligence'!$E:$E,"HIGH") | J20: =A11 | K20: =B11
A21: REDHAT_CVE | B21: =COUNTIF('Threat Intelligence'!$A:$A,A21) | C21: =COUNTIFS('Threat Intelligence'!$A:$A,A21,'Threat Intelligence'!$Q:$Q,"P1") | D21: =COUNTIFS('Threat Intelligence'!$A:$A,A21,'Threat Intelligence'!$Q:$Q,"P2") | E21: =COUNTIFS('Threat Intelligence'!$A:$A,A21,'Threat Intelligence'!$J:$J,"YES") | F21: =COUNTIFS('Threat Intelligence'!$A:$A,A21,'Threat Intelligence'!$E:$E,"CRITICAL") | G21: =COUNTIFS('Threat Intelligence'!$A:$A,A21,'Threat Intelligence'!$E:$E,"HIGH")
A22: SANS_ISC | B22: =COUNTIF('Threat Intelligence'!$A:$A,A22) | C22: =COUNTIFS('Threat Intelligence'!$A:$A,A22,'Threat Intelligence'!$Q:$Q,"P1") | D22: =COUNTIFS('Threat Intelligence'!$A:$A,A22,'Threat Intelligence'!$Q:$Q,"P2") | E22: =COUNTIFS('Threat Intelligence'!$A:$A,A22,'Threat Intelligence'!$J:$J,"YES") | F22: =COUNTIFS('Threat Intelligence'!$A:$A,A22,'Threat Intelligence'!$E:$E,"CRITICAL") | G22: =COUNTIFS('Threat Intelligence'!$A:$A,A22,'Threat Intelligence'!$E:$E,"HIGH")
A23: SHODAN_VULN | B23: =COUNTIF('Threat Intelligence'!$A:$A,A23) | C23: =COUNTIFS('Threat Intelligence'!$A:$A,A23,'Threat Intelligence'!$Q:$Q,"P1") | D23: =COUNTIFS('Threat Intelligence'!$A:$A,A23,'Threat Intelligence'!$Q:$Q,"P2") | E23: =COUNTIFS('Threat Intelligence'!$A:$A,A23,'Threat Intelligence'!$J:$J,"YES") | F23: =COUNTIFS('Threat Intelligence'!$A:$A,A23,'Threat Intelligence'!$E:$E,"CRITICAL") | G23: =COUNTIFS('Threat Intelligence'!$A:$A,A23,'Threat Intelligence'!$E:$E,"HIGH")
A24: TALOS_IP | B24: =COUNTIF('Threat Intelligence'!$A:$A,A24) | C24: =COUNTIFS('Threat Intelligence'!$A:$A,A24,'Threat Intelligence'!$Q:$Q,"P1") | D24: =COUNTIFS('Threat Intelligence'!$A:$A,A24,'Threat Intelligence'!$Q:$Q,"P2") | E24: =COUNTIFS('Threat Intelligence'!$A:$A,A24,'Threat Intelligence'!$J:$J,"YES") | F24: =COUNTIFS('Threat Intelligence'!$A:$A,A24,'Threat Intelligence'!$E:$E,"CRITICAL") | G24: =COUNTIFS('Threat Intelligence'!$A:$A,A24,'Threat Intelligence'!$E:$E,"HIGH")
A25: THREATFOX_IOC | B25: =COUNTIF('Threat Intelligence'!$A:$A,A25) | C25: =COUNTIFS('Threat Intelligence'!$A:$A,A25,'Threat Intelligence'!$Q:$Q,"P1") | D25: =COUNTIFS('Threat Intelligence'!$A:$A,A25,'Threat Intelligence'!$Q:$Q,"P2") | E25: =COUNTIFS('Threat Intelligence'!$A:$A,A25,'Threat Intelligence'!$J:$J,"YES") | F25: =COUNTIFS('Threat Intelligence'!$A:$A,A25,'Threat Intelligence'!$E:$E,"CRITICAL") | G25: =COUNTIFS('Threat Intelligence'!$A:$A,A25,'Threat Intelligence'!$E:$E,"HIGH")
A26: THREATMINER | B26: =COUNTIF('Threat Intelligence'!$A:$A,A26) | C26: =COUNTIFS('Threat Intelligence'!$A:$A,A26,'Threat Intelligence'!$Q:$Q,"P1") | D26: =COUNTIFS('Threat Intelligence'!$A:$A,A26,'Threat Intelligence'!$Q:$Q,"P2") | E26: =COUNTIFS('Threat Intelligence'!$A:$A,A26,'Threat Intelligence'!$J:$J,"YES") | F26: =COUNTIFS('Threat Intelligence'!$A:$A,A26,'Threat Intelligence'!$E:$E,"CRITICAL") | G26: =COUNTIFS('Threat Intelligence'!$A:$A,A26,'Threat Intelligence'!$E:$E,"HIGH")
A27: TOR_EXIT | B27: =COUNTIF('Threat Intelligence'!$A:$A,A27) | C27: =COUNTIFS('Threat Intelligence'!$A:$A,A27,'Threat Intelligence'!$Q:$Q,"P1") | D27: =COUNTIFS('Threat Intelligence'!$A:$A,A27,'Threat Intelligence'!$Q:$Q,"P2") | E27: =COUNTIFS('Threat Intelligence'!$A:$A,A27,'Threat Intelligence'!$J:$J,"YES") | F27: =COUNTIFS('Threat Intelligence'!$A:$A,A27,'Threat Intelligence'!$E:$E,"CRITICAL") | G27: =COUNTIFS('Threat Intelligence'!$A:$A,A27,'Threat Intelligence'!$E:$E,"HIGH")
A28: UBUNTU_SEC | B28: =COUNTIF('Threat Intelligence'!$A:$A,A28) | C28: =COUNTIFS('Threat Intelligence'!$A:$A,A28,'Threat Intelligence'!$Q:$Q,"P1") | D28: =COUNTIFS('Threat Intelligence'!$A:$A,A28,'Threat Intelligence'!$Q:$Q,"P2") | E28: =COUNTIFS('Threat Intelligence'!$A:$A,A28,'Threat Intelligence'!$J:$J,"YES") | F28: =COUNTIFS('Threat Intelligence'!$A:$A,A28,'Threat Intelligence'!$E:$E,"CRITICAL") | G28: =COUNTIFS('Threat Intelligence'!$A:$A,A28,'Threat Intelligence'!$E:$E,"HIGH")
A29: VULNCHECK_KEV | B29: =COUNTIF('Threat Intelligence'!$A:$A,A29) | C29: =COUNTIFS('Threat Intelligence'!$A:$A,A29,'Threat Intelligence'!$Q:$Q,"P1") | D29: =COUNTIFS('Threat Intelligence'!$A:$A,A29,'Threat Intelligence'!$Q:$Q,"P2") | E29: =COUNTIFS('Threat Intelligence'!$A:$A,A29,'Threat Intelligence'!$J:$J,"YES") | F29: =COUNTIFS('Threat Intelligence'!$A:$A,A29,'Threat Intelligence'!$E:$E,"CRITICAL") | G29: =COUNTIFS('Threat Intelligence'!$A:$A,A29,'Threat Intelligence'!$E:$E,"HIGH")
A30: ZDI_ADVISORY | B30: =COUNTIF('Threat Intelligence'!$A:$A,A30) | C30: =COUNTIFS('Threat Intelligence'!$A:$A,A30,'Threat Intelligence'!$Q:$Q,"P1") | D30: =COUNTIFS('Threat Intelligence'!$A:$A,A30,'Threat Intelligence'!$Q:$Q,"P2") | E30: =COUNTIFS('Threat Intelligence'!$A:$A,A30,'Threat Intelligence'!$J:$J,"YES") | F30: =COUNTIFS('Threat Intelligence'!$A:$A,A30,'Threat Intelligence'!$E:$E,"CRITICAL") | G30: =COUNTIFS('Threat Intelligence'!$A:$A,A30,'Threat Intelligence'!$E:$E,"HIGH")
A31: TOTAL | B31: =SUM(B4:B30) | C31: =SUM(C4:C30) | D31: =SUM(D4:D30) | E31: =SUM(E4:E30) | F31: =SUM(F4:F30) | G31: =SUM(G4:G30)
A33: 🔥 RISK HEATMAP ─ Likelihood × Impact | F33: 📐 RISK MATRIX ─ Score = Likelihood × Impact
A34: Likelihood / Impact | B34: Low Impact (1) | C34: Med Impact (2) | D34: High Impact (3) | G34: Impact 1 | H34: Impact 2 | I34: Impact 3 | J34: Zone
A35: Low Likelihood (1) | B35: =COUNTIFS('Threat Intelligence'!$F:$F,1,'Threat Intelligence'!$G:$G,1) | C35: =COUNTIFS('Threat Intelligence'!$F:$F,1,'Threat Intelligence'!$G:$G,2) | D35: =COUNTIFS('Threat Intelligence'!$F:$F,1,'Threat Intelligence'!$G:$G,3) | F35: L=1 (Low) | G35: L1×I1=1 (LOW) | H35: L1×I2=2 (LOW) | I35: L1×I3=3 (MEDIUM) | J35: MEDIUM
A36: Med Likelihood (2) | B36: =COUNTIFS('Threat Intelligence'!$F:$F,2,'Threat Intelligence'!$G:$G,1) | C36: =COUNTIFS('Threat Intelligence'!$F:$F,2,'Threat Intelligence'!$G:$G,2) | D36: =COUNTIFS('Threat Intelligence'!$F:$F,2,'Threat Intelligence'!$G:$G,3) | F36: L=2 (Med) | G36: L2×I1=2 (LOW) | H36: L2×I2=4 (MEDIUM) | I36: L2×I3=6 (HIGH) | J36: HIGH
A37: High Likelihood (3) | B37: =COUNTIFS('Threat Intelligence'!$F:$F,3,'Threat Intelligence'!$G:$G,1) | C37: =COUNTIFS('Threat Intelligence'!$F:$F,3,'Threat Intelligence'!$G:$G,2) | D37: =COUNTIFS('Threat Intelligence'!$F:$F,3,'Threat Intelligence'!$G:$G,3) | F37: L=3 (High) | G37: L3×I1=3 (MEDIUM) | H37: L3×I2=6 (HIGH) | I37: L3×I3=9 (CRITICAL) | J37: CRITICAL
A39: 🟢 LOW | B39: 🟡 MEDIUM | C39: 🟠 HIGH | D39: 🔴 CRITICAL | F39: Risk Score = Likelihood (1-3) × Impact (1-3) → Max 9 = CRITICAL

Sheet Threat Intelligence
A1: Type | B1: ID | C1: Description | D1: CVSS | E1: Severity | F1: Likelihood | G1: Impact | H1: Risk_Level | I1: Final_Score | J1: CISA_KEV | K1: Link | L1: Timestamp | M1: Patch_Available | N1: Patch_Links | O1: Workarounds | P1: Affected_Products | Q1: Remediation_Priority | R1: Remediation_Steps | S1: GreyNoise_Context | T1: EPSS_Score | U1: EPSS_Percentile | V1: MITRE_Techniques | W1: Source_Count | X1: Confidence_Score | Y1: Exploit_Status | Z1: Fix_Available | AA1: Intel_URL | AB1: ZDI_Advisory | AC1: AttackerKB_Score | AD1: News_Coverage
A2: CVE | B2: CVE-2019-25326 | C2: ipPulse 1.92 contains a denial of service vulnerability that allows local attackers to crash the application by providing an oversized input in the Enter Key field. Attackers can generate a 256-byte buffer of repeated 'A' characters to trigger an application crash when pasting the malicious content. | D2: 6.2 | E2: MEDIUM | F2: 2 | G2: 2 | H2: MEDIUM | I2: 10.2 | J2: NO | K2: https://nvd.nist.gov/vuln/detail/CVE-2019-25326 | L2: 2026-02-26 00:15 | M2: CHECK_VENDOR | N2: See NVD references | O2: Apply vendor patches | P2: nwpsw ippulse * | Q2: P4 | R2: 📅 Schedule patch deployment within 30 days | 🔍 Monitor for exploitation attempts | S2: CVE - IP enrichment n/a | T2: 0.0001 | U2: 0.0199 | V2: T1203:Exploitation for Client Execution | T1499:Endpoint Denial of Service | W2: 1 | X2: LOW (40%) | Y2: UNLIKELY | Z2: CHECK_VENDOR | AA2: https://nvd.nist.gov/vuln/detail/CVE-2019-25326 | AB2: NONE | AC2: 0
A3: CVE | B3: CVE-2019-25349 | C3: ScadaApp for iOS 1.1.4.0 contains a denial of service vulnerability that allows attackers to crash the application by inputting an oversized buffer in the Servername field. Attackers can paste a 257-character buffer during login to trigger an application crash on iOS devices. | D3: 7.5 | E3: HIGH | F3: 2 | G3: 3 | H3: HIGH | I3: 13.5 | J3: NO | K3: https://nvd.nist.gov/vuln/detail/CVE-2019-25349 | L3: 2026-02-26 00:15 | M3: CHECK_VENDOR | N3: See NVD references | O3: Apply vendor patches | P3: See CVE details | Q3: P2 | R3: 🚨 URGENT: Apply vendor patches immediately | 🔒 Isolate affected systems if patch unavailable | 🛡️ Enable additional monitoring/IDS rules | S3: CVE - IP enrichment n/a | T3: 0 | U3: 0 | V3: T1203:Exploitation for Client Execution | T1499:Endpoint Denial of Service | W3: 2 | X3: HIGH (72%) | Y3: POSSIBLE | Z3: CHECK_VENDOR | AA3: https://nvd.nist.gov/vuln/detail/CVE-2019-25349 | AB3: NONE | AC3: 3.75
A4: CVE | B4: CVE-2019-25350 | C4: XMedia Recode 3.4.8.6 contains a denial of service vulnerability that allows attackers to crash the application by loading a specially crafted .m3u playlist file. Attackers can create a malicious .m3u file with an oversized buffer to trigger an application crash when the file is opened. | D4: 7.5 | E4: HIGH | F4: 2 | G4: 3 | H4: HIGH | I4: 13.5 | J4: NO | K4: https://nvd.nist.gov/vuln/detail/CVE-2019-25350 | L4: 2026-02-26 00:15 | M4: CHECK_VENDOR | N4: See NVD references | O4: Apply vendor patches | P4: See CVE details | Q4: P3 | R4: 🚨 URGENT: Apply vendor patches immediately | 🔒 Isolate affected systems if patch unavailable | 🛡️ Enable additional monitoring/IDS rules | S4: CVE - IP enrichment n/a | T4: 0 | U4: 0 | V4: T1499:Endpoint Denial of Service | W4: 1 | X4: LOW (40%) | Y4: UNLIKELY | Z4: CHECK_VENDOR | AA4: https://nvd.nist.gov/vuln/detail/CVE-2019-25350 | AB4: NONE | AC4: 0
A5: CVE | B5: CVE-2019-25351 | C5: Centova Cast 3.2.11 contains a file download vulnerability that allows authenticated attackers to retrieve arbitrary system files through the server.copyfile API endpoint. Attackers can exploit the vulnerability by supplying crafted parameters to download sensitive files like /etc/passwd using curl and wget requests. | D5: 8.8 | E5: HIGH | F5: 2 | G5: 3 | H5: HIGH | I5: 14.8 | J5: NO | K5: https://nvd.nist.gov/vuln/detail/CVE-2019-25351 | L5: 2026-02-26 00:15 | M5: CHECK_VENDOR | N5: See NVD references | O5: Apply vendor patches | P5: See CVE details | Q5: P3 | R5: 🚨 URGENT: Apply vendor patches immediately | 🔒 Isolate affected systems if patch unavailable | 🛡️ Enable additional monitoring/IDS rules | S5: CVE - IP enrichment n/a | T5: 0.0005 | U5: 0.1573 | V5: T1190:Exploit Public-Facing Application | W5: 1 | X5: LOW (40%) | Y5: UNLIKELY | Z5: CHECK_VENDOR | AA5: https://nvd.nist.gov/vuln/detail/CVE-2019-25351 | AB5: NONE | AC5: 0
A6: CVE | B6: CVE-2019-25352 | C6: Crystal Live HTTP Server 6.01 contains a directory traversal vulnerability that allows remote attackers to access system files by manipulating URL path segments. Attackers can use multiple '../' sequences to navigate outside the web root and retrieve sensitive configuration files like Windows system files. | D6: 7.5 | E6: HIGH | F6: 2 | G6: 3 | H6: HIGH | I6: 13.5 | J6: NO | K6: https://nvd.nist.gov/vuln/detail/CVE-2019-25352 | L6: 2026-02-26 00:15 | M6: CHECK_VENDOR | N6: See NVD references | O6: Apply vendor patches | P6: See CVE details | Q6: P2 | R6: 🚨 URGENT: Apply vendor patches immediately | 🔒 Isolate affected systems if patch unavailable | 🛡️ Enable additional monitoring/IDS rules | S6: CVE - IP enrichment n/a | T6: 0 | U6: 0 | V6: T1083:File and Directory Discovery | W6: 2 | X6: HIGH (72%) | Y6: POSSIBLE | Z6: CHECK_VENDOR | AA6: https://nvd.nist.gov/vuln/detail/CVE-2019-25352 | AB6: NONE | AC6: 3.75
A7: CVE | B7: CVE-2019-25353 | C7: Foscam Video Management System 1.1.4.9 contains a denial of service vulnerability in the username input field that allows attackers to crash the application. Attackers can overwrite the username with a 520-byte buffer of repeated 'A' characters to trigger an application crash during device login. | D7: 7.5 | E7: HIGH | F7: 2 | G7: 3 | H7: HIGH | I7: 13.5 | J7: NO | K7: https://nvd.nist.gov/vuln/detail/CVE-2019-25353 | L7: 2026-02-26 00:15 | M7: CHECK_VENDOR | N7: See NVD references | O7: Apply vendor patches | P7: See CVE details | Q7: P3 | R7: 🚨 URGENT: Apply vendor patches immediately | 🔒 Isolate affected systems if patch unavailable | 🛡️ Enable additional monitoring/IDS rules | S7: CVE - IP enrichment n/a | T7: 0 | U7: 0 | V7: T1203:Exploitation for Client Execution | T1499:Endpoint Denial of Service | W7: 1 | X7: LOW (40%) | Y7: UNLIKELY | Z7: CHECK_VENDOR | AA7: https://nvd.nist.gov/vuln/detail/CVE-2019-25353 | AB7: NONE | AC7: 0
A8: CVE | B8: CVE-2019-25354 | C8: iSmartViewPro 1.3.34 contains a denial of service vulnerability that allows attackers to crash the application by overflowing the camera ID input field. Attackers can paste a 257-character buffer into the camera DID and password fields to trigger an application crash on iOS devices. | D8: 7.5 | E8: HIGH | F8: 2 | G8: 3 | H8: HIGH | I8: 13.5 | J8: NO | K8: https://nvd.nist.gov/vuln/detail/CVE-2019-25354 | L8: 2026-02-26 00:15 | M8: CHECK_VENDOR | N8: See NVD references | O8: Apply vendor patches | P8: See CVE details | Q8: P2 | R8: 🚨 URGENT: Apply vendor patches immediately | 🔒 Isolate affected systems if patch unavailable | 🛡️ Enable additional monitoring/IDS rules | S8: CVE - IP enrichment n/a | T8: 0 | U8: 0 | V8: T1203:Exploitation for Client Execution | T1499:Endpoint Denial of Service | W8: 2 | X8: HIGH (72%) | Y8: POSSIBLE | Z8: CHECK_VENDOR | AA8: https://nvd.nist.gov/vuln/detail/CVE-2019-25354 | AB8: NONE | AC8: 3.75
A9: CVE | B9: CVE-2019-25355 | C9: gSOAP 2.8 contains a directory traversal vulnerability that allows unauthenticated attackers to access system files by manipulating HTTP path traversal techniques. Attackers can retrieve sensitive files like /etc/passwd by sending crafted GET requests with multiple '../' directory traversal sequences. | D9: 7.5 | E9: HIGH | F9: 2 | G9: 3 | H9: HIGH | I9: 13.5 | J9: NO | K9: https://nvd.nist.gov/vuln/detail/CVE-2019-25355 | L9: 2026-02-26 00:15 | M9: CHECK_VENDOR | N9: See NVD references | O9: Apply vendor patches | P9: See CVE details | Q9: P2 | R9: 🚨 URGENT: Apply vendor patches immediately | 🔒 Isolate affected systems if patch unavailable | 🛡️ Enable additional monitoring/IDS rules | S9: CVE - IP enrichment n/a | T9: 0 | U9: 0 | V9: T1083:File and Directory Discovery | W9: 2 | X9: HIGH (72%) | Y9: POSSIBLE | Z9: CHECK_VENDOR | AA9: https://nvd.nist.gov/vuln/detail/CVE-2019-25355 | AB9: NONE | AC9: 3.75
A10: CVE | B10: CVE-2019-25356 | C10: Bematech (formerly Logic Controls, now Elgin) MP-4200 TH printer contains a cross-site scripting vulnerability in the admin configuration page. Attackers can inject malicious scripts via crafted POST requests with malformed 'admin' and 'person' parameters, allowing execution of arbitrary JavaScript in the context of an authenticated user's browser session. | D10: 6.1 | E10: MEDIUM | F10: 2 | G10: 2 | H10: MEDIUM | I10: 10.1 | J10: NO | K10: https://nvd.nist.gov/vuln/detail/CVE-2019-25356 | L10: 2026-02-26 00:15 | M10: CHECK_VENDOR | N10: See NVD references | O10: Apply vendor patches | P10: See CVE details | Q10: P4 | R10: 📅 Schedule patch deployment within 30 days | 🔍 Monitor for exploitation attempts | S10: CVE - IP enrichment n/a | T10: 0.0004 | U10: 0.1135 | V10: T1189:Drive-by Compromise | W10: 1 | X10: LOW (40%) | Y10: UNLIKELY | Z10: CHECK_VENDOR | AA10: https://nvd.nist.gov/vuln/detail/CVE-2019-25356 | AB10: NONE | AC10: 0
A11: CVE | B11: CVE-2019-25357 | C11: Control Center PRO 6.2.9 contains a stack-based buffer overflow vulnerability in the user creation module's username field that allows attackers to overwrite Structured Exception Handler (SEH). Attackers can craft a malicious payload exceeding 664 bytes to inject shellcode and potentially execute arbitrary code on vulnerable Windows systems. | D11: 8.4 | E11: HIGH | F11: 2 | G11: 3 | H11: HIGH | I11: 14.4 | J11: NO | K11: https://nvd.nist.gov/vuln/detail/CVE-2019-25357 | L11: 2026-02-26 00:15 | M11: CHECK_VENDOR | N11: See NVD references | O11: Apply vendor patches | P11: See CVE details | Q11: P3 | R11: 🚨 URGENT: Apply vendor patches immediately | 🔒 Isolate affected systems if patch unavailable | 🛡️ Enable additional monitoring/IDS rules | S11: CVE - IP enrichment n/a | T11: 0 | U11: 0 | V11: T1190:Exploit Public-Facing Application | T1203:Exploitation for Client Execution | W11: 1 | X11: LOW (40%) | Y11: UNLIKELY | Z11: CHECK_VENDOR | AA11: https://nvd.nist.gov/vuln/detail/CVE-2019-25357 | AB11: NONE | AC11: 0
A12: CVE | B12: CVE-2019-25358 | C12: FileOptimizer 14.00.2524 contains a denial of service vulnerability that allows attackers to crash the application by manipulating the FileOptimizer32.ini configuration file. Attackers can overwrite the TempDirectory parameter with a 5000-character buffer to cause the application to crash when opening options. | D12: 7.5 | E12: HIGH | F12: 2 | G12: 3 | H12: HIGH | I12: 13.5 | J12: NO | K12: https://nvd.nist.gov/vuln/detail/CVE-2019-25358 | L12: 2026-02-26 00:15 | M12: CHECK_VENDOR | N12: See NVD references | O12: Apply vendor patches | P12: See CVE details | Q12: P3 | R12: 🚨 URGENT: Apply vendor patches immediately | 🔒 Isolate affected systems if patch unavailable | 🛡️ Enable additional monitoring/IDS rules | S12: CVE - IP enrichment n/a | T12: 0 | U12: 0 | V12: T1499:Endpoint Denial of Service | W12: 1 | X12: LOW (40%) | Y12: UNLIKELY | Z12: CHECK_VENDOR | AA12: https://nvd.nist.gov/vuln/detail/CVE-2019-25358 | AB12: NONE | AC12: 0
A13: CVE | B13: CVE-2019-25359 | C13: SD.NET RIM versions before 4.7.3c contain a SQL injection vulnerability that allows attackers to inject malicious SQL statements through POST parameters 'idtyp' and 'idgremium'. Attackers can exploit this vulnerability by crafting specially formed POST requests to the /vorlagen/ endpoint, enabling unauthorized database manipulation and potential information disclosure. | D13: 8.2 | E13: HIGH | F13: 2 | G13: 3 | H13: HIGH | I13: 14.2 | J13: NO | K13: https://nvd.nist.gov/vuln/detail/CVE-2019-25359 | L13: 2026-02-26 00:15 | M13: CHECK_VENDOR | N13: See NVD references | O13: Apply vendor patches | P13: See CVE details | Q13: P3 | R13: 🚨 URGENT: Apply vendor patches immediately | 🔒 Isolate affected systems if patch unavailable | 🛡️ Enable additional monitoring/IDS rules | S13: CVE - IP enrichment n/a | T13: 0 | U13: 0 | V13: T1185:Browser Session Hijacking | T1190:Exploit Public-Facing Application | T1213:Data from Information Repositories | W13: 1 | X13: LOW (40%) | Y13: UNLIKELY | Z13: CHECK_VENDOR | AA13: https://nvd.nist.gov/vuln/detail/CVE-2019-25359 | AB13: NONE | AC13: 0
... A1123: CVE | B1123: CVE-2025-11848 | C1123: A null pointer dereference vulnerability in the Wake-on-LAN CGI program of the Zyxel VMG3625-T50B firmware version through 5.50(ABPM.9.6)C0 and the Zyxel WX3100-T0 firmware versions through 5.50(ABVL.4.8)C0 could allow an authenticated attacker with administrator privileges to trigger a denial-of-service (DoS) condition by sending a crafted HTTP request. | D1123: 4.9 | E1123: MEDIUM | F1123: 2 | G1123: 2 | H1123: MEDIUM | I1123: 8.9 | J1123: NO | K1123: https://nvd.nist.gov/vuln/detail/CVE-2025-11848 | L1123: 2026-02-26 00:15 | M1123: YES | N1123: https://www.zyxel.com/global/en/support/security-advisories/zyxel-security-advisory-for-null-pointer-dereference-and-command-injection-vulnerabilities-in-certain-4g-lte-5g-nr-cpe-dsl-ethernet-cpe-fiber-onts-security-routers-and-wireless-extenders-02-24-2026 | O1123: Apply vendor patches | P1123: zyxel vmg4005-b60a_firmware * | zyxel pm7500-00 - | zyxel ex7501-b0 - | Q1123: P4 | R1123: 📅 Schedule patch deployment within 30 days | 🔍 Monitor for exploitation attempts | S1123: CVE - IP enrichment n/a | T1123: 0.0018 | U1123: 0.3897 | V1123: T1499:Endpoint Denial of Service | W1123: 1 | X1123: LOW (40%) | Y1123: UNLIKELY | Z1123: PATCH_AVAILABLE | AA1123: https://nvd.nist.gov/vuln/detail/CVE-2025-11848 | AB1123: NONE | AC1123: 0
A1124: CVE | B1124: CVE-2025-13942 | C1124: A command injection vulnerability in the UPnP function of the Zyxel EX3510-B0 firmware versions through 5.17(ABUP.15.1)C0 could allow a remote attacker to execute operating system (OS) commands on an affected device by sending specially crafted UPnP SOAP requests. | D1124: 9.8 | E1124: CRITICAL | F1124: 2 | G1124: 3 | H1124: HIGH | I1124: 15.8 | J1124: NO | K1124: https://nvd.nist.gov/vuln/detail/CVE-2025-13942 | L1124: 2026-02-26 00:15 | M1124: YES | N1124: https://www.zyxel.com/global/en/support/security-advisories/zyxel-security-advisory-for-null-pointer-dereference-and-command-injection-vulnerabilities-in-certain-4g-lte-5g-nr-cpe-dsl-ethernet-cpe-fiber-onts-security-routers-and-wireless-extenders-02-24-2026 | O1124: Apply vendor patches | P1124: zyxel ex5510-b0 - | zyxel dx4510-b1_firmware * | zyxel dx4510-b0 - | Q1124: P3 | R1124: 🚨 URGENT: Apply vendor patches immediately | 🔒 Isolate affected systems if patch unavailable | 🛡️ Enable additional monitoring/IDS rules | S1124: CVE - IP enrichment n/a | T1124: 0 | U1124: 0 | V1124: T1059:Command and Scripting Interpreter | W1124: 1 | X1124: LOW (40%) | Y1124: UNLIKELY | Z1124: PATCH_AVAILABLE | AA1124: https://nvd.nist.gov/vuln/detail/CVE-2025-13942 | AB1124: NONE | AC1124: 0 | AD1124: [SecurityAffairs] Critical Zyxel router flaw exposed devices to remote attacks
A1125: CVE | B1125: CVE-2025-13943 | C1125: A post-authentication command injection vulnerability in the log file download function of the Zyxel EX3301-T0 firmware versions through 5.50(ABVY.7)C0 could allow an authenticated attacker to execute operating system (OS) commands on an affected device. | D1125: 8.8 | E1125: HIGH | F1125: 2 | G1125: 3 | H1125: HIGH | I1125: 14.8 | J1125: NO | K1125: https://nvd.nist.gov/vuln/detail/CVE-2025-13943 | L1125: 2026-02-26 00:15 | M1125: YES | N1125: https://www.zyxel.com/global/en/support/security-advisories/zyxel-security-advisory-for-null-pointer-dereference-and-command-injection-vulnerabilities-in-certain-4g-lte-5g-nr-cpe-dsl-ethernet-cpe-fiber-onts-security-routers-and-wireless-extenders-02-24-2026 | O1125: Apply vendor patches | P1125: zyxel vmg4005-b60a_firmware * | zyxel pm7500-00 - | zyxel ex7501-b0 - | Q1125: P3 | R1125: 🚨 URGENT: Apply vendor patches immediately | 🔒 Isolate affected systems if patch unavailable | 🛡️ Enable additional monitoring/IDS rules | S1125: CVE - IP enrichment n/a | T1125: 0 | U1125: 0 | V1125: T1059:Command and Scripting Interpreter | W1125: 1 | X1125: LOW (40%) | Y1125: UNLIKELY | Z1125: PATCH_AVAILABLE | AA1125: https://nvd.nist.gov/vuln/detail/CVE-2025-13943 | AB1125: NONE | AC1125: 0
A1126: CVE | B1126: CVE-2026-1459 | C1126: A post-authentication command injection vulnerability in the TR-369 certificate download CGI program of the Zyxel VMG3625-T50B firmware versions through 5.50(ABPM.9.7)C0 could allow an authenticated attacker with administrator privileges to execute operating system (OS) commands on an affected device. | D1126: 7.2 | E1126: HIGH | F1126: 2 | G1126: 3 | H1126: HIGH | I1126: 13.2 | J1126: NO | K1126: https://nvd.nist.gov/vuln/detail/CVE-2026-1459 | L1126: 2026-02-26 00:15 | M1126: YES | N1126: https://www.zyxel.com/global/en/support/security-advisories/zyxel-security-advisory-for-null-pointer-dereference-and-command-injection-vulnerabilities-in-certain-4g-lte-5g-nr-cpe-dsl-ethernet-cpe-fiber-onts-security-routers-and-wireless-extenders-02-24-2026 | O1126: Apply vendor patches | P1126: zyxel vmg3625-t50b - | zyxel emg5523-t50b_firmware * | zyxel emg3525-t50b - | Q1126: P3 | R1126: 🚨 URGENT: Apply vendor patches immediately | 🔒 Isolate affected systems if patch unavailable | 🛡️ Enable additional monitoring/IDS rules | S1126: CVE - IP enrichment n/a | T1126: 0 | U1126: 0 | V1126: T1059:Command and Scripting Interpreter | W1126: 1 | X1126: LOW (40%) | Y1126: UNLIKELY | Z1126: PATCH_AVAILABLE | AA1126: https://nvd.nist.gov/vuln/detail/CVE-2026-1459 | AB1126: NONE | AC1126: 0
A1127: CVE | B1127: CVE-2026-25989 | C1127: ImageMagick is free and open-source software used for editing and manipulating digital images. Prior to versions 7.1.2-15 and 6.9.13-40, a crafted SVG file can cause a denial of service. An off-by-one boundary check (`>` instead of `>=`) that allows bypass the guard and reach an undefined `(size_t)` cast. Versions 7.1.2-15 and 6.9.13-40 contain a patch. | D1127: 7.5 | E1127: HIGH | F1127: 2 | G1127: 3 | H1127: HIGH | I1127: 13.5 | J1127: NO | K1127: https://nvd.nist.gov/vuln/detail/CVE-2026-25989 | L1127: 2026-02-26 00:15 | M1127: YES | N1127: https://github.com/ImageMagick/ImageMagick/security/advisories/GHSA-7355-pwx2-pm84 | O1127: Apply vendor patches | P1127: imagemagick imagemagick * | Q1127: P3 | R1127: 🚨 URGENT: Apply vendor patches immediately | 🔒 Isolate affected systems if patch unavailable | 🛡️ Enable additional monitoring/IDS rules | S1127: CVE - IP enrichment n/a | T1127: 0 | U1127: 0 | V1127: T1190:Exploit Public-Facing Application | T1499:Endpoint Denial of Service | W1127: 1 | X1127: LOW (40%) | Y1127: UNLIKELY | Z1127: PATCH_AVAILABLE | AA1127: https://nvd.nist.gov/vuln/detail/CVE-2026-25989 | AB1127: NONE | AC1127: 0
A1128: CVE | B1128: CVE-2026-26066 | C1128: ImageMagick is free and open-source software used for editing and manipulating digital images. Prior to versions 7.1.2-15 and 6.9.13-40, a crafted profile contain invalid IPTC data may cause an infinite loop when writing it with `IPTCTEXT`. Versions 7.1.2-15 and 6.9.13-40 contain a patch. | D1128: 6.2 | E1128: MEDIUM | F1128: 2 | G1128: 2 | H1128: MEDIUM | I1128: 10.2 | J1128: NO | K1128: https://nvd.nist.gov/vuln/detail/CVE-2026-26066 | L1128: 2026-02-26 00:15 | M1128: CHECK_VENDOR | N1128: See NVD references | O1128: Apply vendor patches | P1128: imagemagick imagemagick * | Q1128: P4 | R1128: 📅 Schedule patch deployment within 30 days | 🔍 Monitor for exploitation attempts | S1128: CVE - IP enrichment n/a | T1128: 0 | U1128: 0 | V1128: T1190:Exploit Public-Facing Application | W1128: 1 | X1128: LOW (40%) | Y1128: UNLIKELY | Z1128: CHECK_VENDOR | AA1128: https://nvd.nist.gov/vuln/detail/CVE-2026-26066 | AB1128: NONE | AC1128: 0
A1129: CVE | B1129: CVE-2026-26198 | C1129: Ormar is a async mini ORM for Python. In versions 0.9.9 through 0.22.0, when performing aggregate queries, Ormar ORM constructs SQL expressions by passing user-supplied column names directly into `sqlalchemy.text()` without any validation or sanitization. The `min()` and `max()` methods in the `QuerySet` class accept arbitrary string input as the column parameter. While `sum()` and `avg()` are partially protected by an `is_numeric` type check that rejects non-existent fields, `min()` and `max()` | D1129: 9.8 | E1129: CRITICAL | F1129: 2 | G1129: 3 | H1129: HIGH | I1129: 15.8 | J1129: NO | K1129: https://nvd.nist.gov/vuln/detail/CVE-2026-26198 | L1129: 2026-02-26 00:15 | M1129: YES | N1129: https://github.com/collerek/ormar/commit/a03bae14fe01358d3eaf7e319fcd5db2e4956b16 | https://github.com/collerek/ormar/security/advisories/GHSA-xxh2-68g9-8jqr | O1129: Apply vendor patches | P1129: collerek ormar * | Q1129: P3 | R1129: 🚨 URGENT: Apply vendor patches immediately | 🔒 Isolate affected systems if patch unavailable | 🛡️ Enable additional monitoring/IDS rules | S1129: CVE - IP enrichment n/a | T1129: 0 | U1129: 0 | V1129: T1190:Exploit Public-Facing Application | W1129: 1 | X1129: LOW (40%) | Y1129: UNLIKELY | Z1129: PATCH_AVAILABLE | AA1129: https://nvd.nist.gov/vuln/detail/CVE-2026-26198 | AB1129: NONE | AC1129: 0
A1130: CVE | B1130: CVE-2026-26283 | C1130: ImageMagick is free and open-source software used for editing and manipulating digital images. Prior to versions 7.1.2-15 and 6.9.13-40, a `continue` statement in the JPEG extent binary search loop in the jpeg encoder causes an infinite loop when writing persistently fails. An attacker can trigger a 100% CPU consumption and process hang (Denial of Service) with a crafted image. Versions 7.1.2-15 and 6.9.13-40 contain a patch. | D1130: 6.2 | E1130: MEDIUM | F1130: 2 | G1130: 2 | H1130: MEDIUM | I1130: 10.2 | J1130: NO | K1130: https://nvd.nist.gov/vuln/detail/CVE-2026-26283 | L1130: 2026-02-26 00:15 | M1130: YES | N1130: https://github.com/ImageMagick/ImageMagick/security/advisories/GHSA-gwr3-x37h-h84v | O1130: Apply vendor patches | P1130: imagemagick imagemagick * | Q1130: P4 | R1130: 📅 Schedule patch deployment within 30 days | 🔍 Monitor for exploitation attempts | S1130: CVE - IP enrichment n/a | T1130: 0 | U1130: 0 | V1130: T1190:Exploit Public-Facing Application | T1499:Endpoint Denial of Service | W1130: 1 | X1130: LOW (40%) | Y1130: UNLIKELY | Z1130: PATCH_AVAILABLE | AA1130: https://nvd.nist.gov/vuln/detail/CVE-2026-26283 | AB1130: NONE | AC1130: 0
A1131: CVE | B1131: CVE-2026-26284 | C1131: ImageMagick is free and open-source software used for editing and manipulating digital images. Prior to versions 7.1.2-15 and 6.9.13-40, ImageMagick lacks proper boundary checking when processing Huffman-coded data from PCD (Photo CD) files. The decoder contains an function that has an incorrect initialization that could cause an out of bounds read. Versions 7.1.2-15 and 6.9.13-40 contain a patch. | D1131: 6.5 | E1131: MEDIUM | F1131: 2 | G1131: 2 | H1131: MEDIUM | I1131: 10.5 | J1131: NO | K1131: https://nvd.nist.gov/vuln/detail/CVE-2026-26284 | L1131: 2026-02-26 00:15 | M1131: YES | N1131: https://github.com/ImageMagick/ImageMagick/security/advisories/GHSA-wrhr-rf8j-r842 | O1131: Apply vendor patches | P1131: imagemagick imagemagick * | Q1131: P4 | R1131: 📅 Schedule patch deployment within 30 days | 🔍 Monitor for exploitation attempts | S1131: CVE - IP enrichment n/a | T1131: 0.0004 | U1131: 0.1313 | V1131: T1203:Exploitation for Client Execution | T1190:Exploit Public-Facing Application | W1131: 1 | X1131: LOW (40%) | Y1131: UNLIKELY | Z1131: PATCH_AVAILABLE | AA1131: https://nvd.nist.gov/vuln/detail/CVE-2026-26284 | AB1131: NONE | AC1131: 0
A1132: CVE | B1132: CVE-2026-26331 | C1132: yt-dlp is a command-line audio/video downloader. Starting in version 2023.06.21 and prior to version 2026.02.21, when yt-dlp's `--netrc-cmd` command-line option (or `netrc_cmd` Python API parameter) is used, an attacker could achieve arbitrary command injection on the user's system with a maliciously crafted URL. yt-dlp maintainers assume the impact of this vulnerability to be high for anyone who uses `--netrc-cmd` in their command/configuration or `netrc_cmd` in their Python scripts. Even thoug | D1132: 8.8 | E1132: HIGH | F1132: 2 | G1132: 3 | H1132: HIGH | I1132: 14.8 | J1132: NO | K1132: https://nvd.nist.gov/vuln/detail/CVE-2026-26331 | L1132: 2026-02-26 00:15 | M1132: YES | N1132: https://github.com/yt-dlp/yt-dlp/commit/1fbbe29b99dc61375bf6d786f824d9fcf6ea9c1a | https://github.com/yt-dlp/yt-dlp/security/advisories/GHSA-g3gw-q23r-pgqm | O1132: https://github.com/yt-dlp/yt-dlp/security/advisories/GHSA-g3gw-q23r-pgqm | P1132: yt-dlp_project yt-dlp * | Q1132: P3 | R1132: 🚨 URGENT: Apply vendor patches immediately | 🔒 Isolate affected systems if patch unavailable | 🛡️ Enable additional monitoring/IDS rules | S1132: CVE - IP enrichment n/a | T1132: 0 | U1132: 0 | V1132: T1059:Command and Scripting Interpreter | W1132: 1 | X1132: LOW (40%) | Y1132: UNLIKELY | Z1132: PATCH_AVAILABLE | AA1132: https://nvd.nist.gov/vuln/detail/CVE-2026-26331 | AB1132: NONE | AC1132: 0
A1133: CVE | B1133: CVE-2026-26981 | C1133: OpenEXR provides the specification and reference implementation of the EXR file format, an image storage format for the motion picture industry. In versions 3.3.0 through 3.3.6 and 3.4.0 through 3.4.4, a heap-buffer-overflow (OOB read) occurs in the `istream_nonparallel_read` function in `ImfContextInit.cpp` when parsing a malformed EXR file through a memory-mapped `IStream`. A signed integer subtraction produces a negative value that is implicitly converted to `size_t`, resulting in a massive l | D1133: 6.5 | E1133: MEDIUM | F1133: 2 | G1133: 2 | H1133: MEDIUM | I1133: 10.5 | J1133: NO | K1133: https://nvd.nist.gov/vuln/detail/CVE-2026-26981 | L1133: 2026-02-26 00:15 | M1133: YES | N1133: https://github.com/AcademySoftwareFoundation/openexr/commit/6bb2ddf1068573d073edf81270a015b38cc05cef | https://github.com/AcademySoftwareFoundation/openexr/commit/d2be382758adc3e9ab83a3de35138ec28d93ebd8 | https://github.com/AcademySoftwareFoundation/openexr/security/advisories/GHSA-q6vj-wxvf-5m8c | O1133: Apply vendor patches | P1133: openexr openexr * | Q1133: P4 | R1133: 📅 Schedule patch deployment within 30 days | 🔍 Monitor for exploitation attempts | S1133: CVE - IP enrichment n/a | T1133: 0 | U1133: 0 | V1133: T1190:Exploit Public-Facing Application | W1133: 1 | X1133: LOW (40%) | Y1133: UNLIKELY | Z1133: PATCH_AVAILABLE | AA1133: https://nvd.nist.gov/vuln/detail/CVE-2026-26981 | AB1133: NONE | AC1133: 0
A1134: CVE | B1134: CVE-2026-26983 | C1134: ImageMagick is free and open-source software used for editing and manipulating digital images. Prior to versions 7.1.2-15 and 6.9.13-40, the MSL interpreter crashes when processing a invalid ` ` element that causes it to use an image after it has been freed. Versions 7.1.2-15 and 6.9.13-40 contain a patch. | D1134: 5.3 | E1134: MEDIUM | F1134: 2 | G1134: 2 | H1134: MEDIUM | I1134: 9.3 | J1134: NO | K1134: https://nvd.nist.gov/vuln/detail/CVE-2026-26983 | L1134: 2026-02-26 00:15 | M1134: YES | N1134: https://github.com/ImageMagick/ImageMagick/security/advisories/GHSA-w8mw-frc6-r7m8 | O1134: Apply vendor patches | P1134: imagemagick imagemagick * | Q1134: P4 | R1134: 📅 Schedule patch deployment within 30 days | 🔍 Monitor for exploitation attempts | S1134: CVE - IP enrichment n/a | T1134: 0 | U1134: 0 | V1134: T1499:Endpoint Denial of Service | T1203:Exploitation for Client Execution | T1190:Exploit Public-Facing Application | W1134: 1 | X1134: LOW (40%) | Y1134: UNLIKELY | Z1134: PATCH_AVAILABLE | AA1134: https://nvd.nist.gov/vuln/detail/CVE-2026-26983 | AB1134: NONE | AC1134: 0
A1135: CVE | B1135: CVE-2026-27126 | C1135: Craft is a content management system (CMS). In versions 4.5.0-RC1 through 4.16.18 and 5.0.0-RC1 through 5.8.22, a stored Cross-site Scripting (XSS) vulnerability exists in the `editableTable.twig` component when using the `html` column type. The application fails to sanitize the input, allowing an attacker to execute arbitrary JavaScript when another user views a page with the malicious table field. In order to exploit the vulnerability, an attacker must have an administrator account, and `allow | D1135: 5 | E1135: MEDIUM | F1135: 2 | G1135: 2 | H1135: MEDIUM | I1135: 9 | J1135: NO | K1135: https://nvd.nist.gov/vuln/detail/CVE-2026-27126 | L1135: 2026-02-26 00:15 | M1135: CHECK_VENDOR | N1135: See NVD references | O1135: Apply vendor patches | P1135: See CVE details | Q1135: P4 | R1135: 📅 Schedule patch deployment within 30 days | 🔍 Monitor for exploitation attempts | S1135: CVE - IP enrichment n/a | T1135: 0 | U1135: 0 | V1135: T1189:Drive-by Compromise | W1135: 1 | X1135: LOW (40%) | Y1135: UNLIKELY | Z1135: CHECK_VENDOR | AA1135: https://nvd.nist.gov/vuln/detail/CVE-2026-27126 | AB1135: NONE | AC1135: 0
A1136: CVE | B1136: CVE-2026-27127 | C1136: Craft is a content management system (CMS). In versions 4.5.0-RC1 through 4.16.18 and 5.0.0-RC1 through 5.8.22, the SSRF validation in Craft CMS’s GraphQL Asset mutation performs DNS resolution separately from the HTTP request. This Time-of-Check-Time-of-Use (TOCTOU) vulnerability enables DNS rebinding attacks, where an attacker’s DNS server returns different IP addresses for validation compared to the actual request. This is a bypass of the security fix for CVE-2025-68437 that allows access to | D1136: 6.3 | E1136: MEDIUM | F1136: 2 | G1136: 2 | H1136: MEDIUM | I1136: 10.3 | J1136: NO | K1136: https://nvd.nist.gov/vuln/detail/CVE-2026-27127 | L1136: 2026-02-26 00:15 | M1136: YES | N1136: https://github.com/craftcms/cms/commit/a4cf3fb63bba3249cf1e2882b18a2d29e77a8575 | https://github.com/craftcms/cms/security/advisories/GHSA-gp2f-7wcm-5fhx | https://github.com/craftcms/cms/security/advisories/GHSA-x27p-wfqw-hfcc | O1136: https://github.com/craftcms/cms/security/advisories/GHSA-gp2f-7wcm-5fhx | P1136: craftcms craft_cms * | craftcms craft_cms 3.5.0 | Q1136: P4 | R1136: 📅 Schedule patch deployment within 30 days | 🔍 Monitor for exploitation attempts | S1136: CVE - IP enrichment n/a | T1136: 0 | U1136: 0 | V1136: T1090:Proxy | W1136: 1 | X1136: LOW (40%) | Y1136: UNLIKELY | Z1136: PATCH_AVAILABLE | AA1136: https://nvd.nist.gov/vuln/detail/CVE-2026-27127 | AB1136: NONE | AC1136: 0
... A1152: CVE | B1152: CVE-2026-24314 | C1152: Under certain conditions SAP S/4HANA (Manage Payment Media) allows an authenticated attacker to access information which would otherwise be restricted. This could cause low impact on confidentiality of the application while integrity and availability are not impacted. | D1152: 4.3 | E1152: MEDIUM | F1152: 2 | G1152: 2 | H1152: MEDIUM | I1152: 8.3 | J1152: NO | K1152: https://nvd.nist.gov/vuln/detail/CVE-2026-24314 | L1152: 2026-02-26 00:15 | M1152: CHECK_VENDOR | N1152: See NVD references | O1152: Apply vendor patches | P1152: See CVE details | Q1152: P4 | R1152: 📅 Schedule patch deployment within 30 days | 🔍 Monitor for exploitation attempts | S1152: CVE - IP enrichment n/a | T1152: 0.0003 | U1152: 0.0741 | V1152: T1190:Exploit Public-Facing Application | W1152: 1 | X1152: LOW (40%) | Y1152: UNLIKELY | Z1152: CHECK_VENDOR | AA1152: https://nvd.nist.gov/vuln/detail/CVE-2026-24314 | AB1152: NONE | AC1152: 0
A1153: CVE | B1153: CVE-2025-40538 | C1153: A broken access control vulnerability exists in Serv-U which when exploited, gives a malicious actor the ability to create a system admin user and execute arbitrary code as a privileged account via domain admin or group admin privileges. This issue requires administrative privileges to abuse. On Windows deployments, the risk is scored as a medium because services frequently run under less-privileged service accounts by default. | D1153: 9.1 | E1153: CRITICAL | F1153: 2 | G1153: 3 | H1153: HIGH | I1153: 15.1 | J1153: NO | K1153: https://nvd.nist.gov/vuln/detail/CVE-2025-40538 | L1153: 2026-02-26 00:15 | M1153: YES | N1153: https://documentation.solarwinds.com/en/success_center/servu/content/release_notes/servu_15-5-4_release_notes.htm | https://www.solarwinds.com/trust-center/security-advisories/CVE-2025-40538 | O1153: Apply vendor patches | P1153: solarwinds serv-u * | Q1153: P3 | R1153: 🚨 URGENT: Apply vendor patches immediately | 🔒 Isolate affected systems if patch unavailable | 🛡️ Enable additional monitoring/IDS rules | S1153: CVE - IP enrichment n/a | T1153: 0 | U1153: 0 | V1153: T1203:Exploitation for Client Execution | W1153: 1 | X1153: LOW (40%) | Y1153: UNLIKELY | Z1153: PATCH_AVAILABLE | AA1153: https://nvd.nist.gov/vuln/detail/CVE-2025-40538 | AB1153: NONE | AC1153: 0 | AD1153: [TheHackerNews] SolarWinds Patches 4 Critical Serv-U 15.5 Flaws Allowing Root Code Exe
A1154: CVE | B1154: CVE-2025-40539 | C1154: A type confusion vulnerability exists in Serv-U which when exploited, gives a malicious actor the ability to execute arbitrary native code as privileged account. This issue requires administrative privileges to abuse. On Windows deployments, the risk is scored as a medium because services frequently run under less-privileged service accounts by default. | D1154: 9.1 | E1154: CRITICAL | F1154: 2 | G1154: 3 | H1154: HIGH | I1154: 15.1 | J1154: NO | K1154: https://nvd.nist.gov/vuln/detail/CVE-2025-40539 | L1154: 2026-02-26 00:15 | M1154: YES | N1154: https://documentation.solarwinds.com/en/success_center/servu/content/release_notes/servu_15-5-4_release_notes.htm | https://www.solarwinds.com/trust-center/security-advisories/CVE-2025-40539 | O1154: Apply vendor patches | P1154: solarwinds serv-u * | Q1154: P3 | R1154: 🚨 URGENT: Apply vendor patches immediately | 🔒 Isolate affected systems if patch unavailable | 🛡️ Enable additional monitoring/IDS rules | S1154: CVE - IP enrichment n/a | T1154: 0 | U1154: 0 | V1154: T1190:Exploit Public-Facing Application | W1154: 1 | X1154: LOW (40%) | Y1154: UNLIKELY | Z1154: PATCH_AVAILABLE | AA1154: https://nvd.nist.gov/vuln/detail/CVE-2025-40539 | AB1154: NONE | AC1154: 0
A1155: CVE | B1155: CVE-2025-40540 | C1155: A type confusion vulnerability exists in Serv-U which when exploited, gives a malicious actor the ability to execute arbitrary native code as privileged account. This issue requires administrative privileges to abuse. On Windows deployments, the risk is scored as a medium because services frequently run under less-privileged service accounts by default. | D1155: 9.1 | E1155: CRITICAL | F1155: 2 | G1155: 3 | H1155: HIGH | I1155: 15.1 | J1155: NO | K1155: https://nvd.nist.gov/vuln/detail/CVE-2025-40540 | L1155: 2026-02-26 00:15 | M1155: YES | N1155: https://documentation.solarwinds.com/en/success_center/servu/content/release_notes/servu_15-5-4_release_notes.htm | https://www.solarwinds.com/trust-center/security-advisories/CVE-2025-40540 | O1155: Apply vendor patches | P1155: solarwinds serv-u * | Q1155: P3 | R1155: 🚨 URGENT: Apply vendor patches immediately | 🔒 Isolate affected systems if patch unavailable | 🛡️ Enable additional monitoring/IDS rules | S1155: CVE - IP enrichment n/a | T1155: 0 | U1155: 0 | V1155: T1190:Exploit Public-Facing Application | W1155: 1 | X1155: LOW (40%) | Y1155: UNLIKELY | Z1155: PATCH_AVAILABLE | AA1155: https://nvd.nist.gov/vuln/detail/CVE-2025-40540 | AB1155: NONE | AC1155: 0
A1156: CVE | B1156: CVE-2025-40541 | C1156: An Insecure Direct Object Reference (IDOR) vulnerability exists in Serv-U, which when exploited, gives a malicious actor the ability to execute native code as a privileged account. This issue requires administrative privileges to abuse. On Windows deployments, the risk is scored as a medium because services frequently run under less-privileged service accounts by default. | D1156: 9.1 | E1156: CRITICAL | F1156: 2 | G1156: 3 | H1156: HIGH | I1156: 15.1 | J1156: NO | K1156: https://nvd.nist.gov/vuln/detail/CVE-2025-40541 | L1156: 2026-02-26 00:15 | M1156: YES | N1156: https://documentation.solarwinds.com/en/success_center/servu/content/release_notes/servu_15-5-4_release_notes.htm | https://www.solarwinds.com/trust-center/security-advisories/CVE-2025-40541 | O1156: Apply vendor patches | P1156: solarwinds serv-u * | Q1156: P3 | R1156: 🚨 URGENT: Apply vendor patches immediately | 🔒 Isolate affected systems if patch unavailable | 🛡️ Enable additional monitoring/IDS rules | S1156: CVE - IP enrichment n/a | T1156: 0 | U1156: 0 | V1156: T1190:Exploit Public-Facing Application | W1156: 1 | X1156: LOW (40%) | Y1156: UNLIKELY | Z1156: PATCH_AVAILABLE | AA1156: https://nvd.nist.gov/vuln/detail/CVE-2025-40541 | AB1156: NONE | AC1156: 0
A1157: CVE | B1157: CVE-2026-1229 | C1157: The CombinedMult function in the CIRCL ecc/p384 package (secp384r1 curve) produces an incorrect value for specific inputs. The issue is fixed by using complete addition formulas. ECDH and ECDSA signing relying on this curve are not affected. The bug was fixed in v1.6.3 https://github.com/cloudflare/circl/releases/tag/v1.6.3 . | D1157: 5 | E1157: MEDIUM | F1157: 2 | G1157: 2 | H1157: MEDIUM | I1157: 9 | J1157: NO | K1157: https://nvd.nist.gov/vuln/detail/CVE-2026-1229 | L1157: 2026-02-26 00:15 | M1157: CHECK_VENDOR | N1157: See NVD references | O1157: Apply vendor patches | P1157: See CVE details | Q1157: P4 | R1157: 📅 Schedule patch deployment within 30 days | 🔍 Monitor for exploitation attempts | S1157: CVE - IP enrichment n/a | T1157: 0 | U1157: 0 | V1157: T1190:Exploit Public-Facing Application | W1157: 1 | X1157: LOW (40%) | Y1157: UNLIKELY | Z1157: CHECK_VENDOR | AA1157: https://nvd.nist.gov/vuln/detail/CVE-2026-1229 | AB1157: NONE | AC1157: 0
A1158: CVE | B1158: CVE-2024-1524 | C1158: When the "Silent Just-In-Time Provisioning" feature is enabled for a federated identity provider (IDP) there is a risk that a local user store user's information may be replaced during the account provisioning process in cases where federated users share the same username as local users. There will be no impact on your deployment if any of the preconditions mentioned below are not met. Only when all the preconditions mentioned below are fulfilled could a malicious actor associate a targeted | D1158: 7.7 | E1158: HIGH | F1158: 2 | G1158: 3 | H1158: HIGH | I1158: 13.7 | J1158: NO | K1158: https://nvd.nist.gov/vuln/detail/CVE-2024-1524 | L1158: 2026-02-26 00:15 | M1158: CHECK_VENDOR | N1158: See NVD references | O1158: Apply vendor patches | P1158: See CVE details | Q1158: P3 | R1158: 🚨 URGENT: Apply vendor patches immediately | 🔒 Isolate affected systems if patch unavailable | 🛡️ Enable additional monitoring/IDS rules | S1158: CVE - IP enrichment n/a | T1158: 0.0005 | U1158: 0.1519 | V1158: T1190:Exploit Public-Facing Application | W1158: 1 | X1158: LOW (40%) | Y1158: UNLIKELY | Z1158: CHECK_VENDOR | AA1158: https://nvd.nist.gov/vuln/detail/CVE-2024-1524 | AB1158: NONE | AC1158: 0
A1159: CVE | B1159: CVE-2025-11165 | C1159: A sandbox escape vulnerability exists in dotCMS’s Velocity scripting engine (VTools) that allows authenticated users with scripting privileges to bypass class and package restrictions enforced by SecureUberspectorImpl. By dynamically modifying the Velocity engine’s runtime configuration and reinitializing its Uberspect, a malicious actor can remove the introspector.restrict.classes and introspector.restrict.packages protections. Once these restrictions are cleared, the attacker can access arbi | D1159: 8.5 | E1159: HIGH | F1159: 2 | G1159: 3 | H1159: HIGH | I1159: 14.5 | J1159: NO | K1159: https://nvd.nist.gov/vuln/detail/CVE-2025-11165 | L1159: 2026-02-26 00:15 | M1159: CHECK_VENDOR | N1159: See NVD references | O1159: Apply vendor patches | P1159: See CVE details | Q1159: P3 | R1159: 🚨 URGENT: Apply vendor patches immediately | 🔒 Isolate affected systems if patch unavailable | 🛡️ Enable additional monitoring/IDS rules | S1159: CVE - IP enrichment n/a | T1159: 0 | U1159: 0 | V1159: T1190:Exploit Public-Facing Application | W1159: 1 | X1159: LOW (40%) | Y1159: UNLIKELY | Z1159: CHECK_VENDOR | AA1159: https://nvd.nist.gov/vuln/detail/CVE-2025-11165 | AB1159: NONE | AC1159: 0
A1160: CVE | B1160: CVE-2024-56373 | C1160: DAG Author (who already has quite a lot of permissions) could manipulate database of Airflow 2 in the way to execute arbitrary code in the web-server context, which they should normally not be able to do, leading to potentially remote code execution in the context of web-server (server-side) as a result of a user viewing historical task information. The functionality responsible for that (log template history) has been disabled by default in 2.11.1 and users should upgrade to Airflow 3 if they | D1160: 8.4 | E1160: HIGH | F1160: 2 | G1160: 3 | H1160: HIGH | I1160: 14.4 | J1160: NO | K1160: https://nvd.nist.gov/vuln/detail/CVE-2024-56373 | L1160: 2026-02-26 00:15 | M1160: YES | N1160: https://lists.apache.org/thread/2vrmrhcht6g7cp5yjxpnrk2wtrncm6cy | O1160: Apply vendor patches | P1160: apache airflow * | Q1160: P1 | R1160: 🚨 URGENT: Apply vendor patches immediately | 🔒 Isolate affected systems if patch unavailable | 🛡️ Enable additional monitoring/IDS rules | S1160: CVE - IP enrichment n/a | T1160: 0 | U1160: 0 | V1160: T1059:Command and Scripting Interpreter | T1190:Exploit Public-Facing Application | T1210:Exploitation of Remote Services | W1160: 2 | X1160: HIGH (72%) | Y1160: HIGH | Z1160: PATCH_AVAILABLE | AA1160: https://nvd.nist.gov/vuln/detail/CVE-2024-56373 | AB1160: http://www.zerodayinitiative.com/advisories/ZDI-26-123/ | AC1160: 0
A1161: CVE | B1161: CVE-2025-27555 | C1161: Airflow versions before 2.11.1 have a vulnerability that allows authenticated users with audit log access to see sensitive values in audit logs which they should not see. When sensitive connection parameters were set via airflow CLI, values of those variables appeared in the audit log and were stored unencrypted in the Airflow database. While this risk is limited to users with audit log access, it is recommended to upgrade to Airflow 2.11.1 or a later version, which addresses this issue. Users w | D1161: 6.5 | E1161: MEDIUM | F1161: 2 | G1161: 2 | H1161: MEDIUM | I1161: 10.5 | J1161: NO | K1161: https://nvd.nist.gov/vuln/detail/CVE-2025-27555 | L1161: 2026-02-26 00:15 | M1161: YES | N1161: https://lists.apache.org/thread/nxovkp319jo8vg498gql1yswtb2frbkw | O1161: Apply vendor patches | P1161: apache airflow * | Q1161: P1 | R1161: 📅 Schedule patch deployment within 30 days | 🔍 Monitor for exploitation attempts | S1161: CVE - IP enrichment n/a | T1161: 0.0003 | U1161: 0.0968 | V1161: T1190:Exploit Public-Facing Application | W1161: 2 | X1161: HIGH (72%) | Y1161: HIGH | Z1161: PATCH_AVAILABLE | AA1161: https://nvd.nist.gov/vuln/detail/CVE-2025-27555 | AB1161: http://www.zerodayinitiative.com/advisories/ZDI-26-123/ | AC1161: 0
A1162: CVE | B1162: CVE-2026-2664 | C1162: An out of bounds read vulnerability in the grpcfuse kernel module present in the Linux VM in Docker Desktop for Windows, Linux and macOS up to version 4.61.0 could allow a local attacker to cause an unspecified impact by writing to /proc/docker entries. The issue has been fixed in Docker Desktop 4.62.0 . | D1162: 5 | E1162: MEDIUM | F1162: 2 | G1162: 2 | H1162: MEDIUM | I1162: 9 | J1162: NO | K1162: https://nvd.nist.gov/vuln/detail/CVE-2026-2664 | L1162: 2026-02-26 00:15 | M1162: CHECK_VENDOR | N1162: See NVD references | O1162: Apply vendor patches | P1162: See CVE details | Q1162: P1 | R1162: 📅 Schedule patch deployment within 30 days | 🔍 Monitor for exploitation attempts | S1162: CVE - IP enrichment n/a | T1162: 0 | U1162: 0 | V1162: T1203:Exploitation for Client Execution | W1162: 2 | X1162: HIGH (72%) | Y1162: HIGH | Z1162: CHECK_VENDOR | AA1162: https://nvd.nist.gov/vuln/detail/CVE-2026-2664 | AB1162: http://www.zerodayinitiative.com/advisories/ZDI-26-125/ | AC1162: 0
